Workbook

Sheet Overall 
A1: August Month Performance Report
A2: S.No | B2: Counsellor Name | C2: Agency Name | D2: DOJ | E2: Email ID | F2: Team Name | G2: Overall | H2: Non-Negotiable | I2: Achieved | J2: Pending | K2: % Achieved
A3: 1 | B3: Abhishek Kumar Singh | C3: SKS Enterprises | D3: 46106 | E3: c-abhishek.singh@bennett.edu.in | F3: Engineering | G3: 50 | H3: 40 | J3: =I3-G3 -> -50 | K3: =I3/G3 -> 0 | M3: Aug Month Targets
A4: 2 | B4: Akshat Sharma | C4: SKS Enterprises | D4: 46020 | E4: c-akshat.sharma@bennett.edu.in | F4: Engineering | G4: 50 | H4: 40 | J4: =I4-G4 -> -50 | K4: =I4/G4 -> 0 | M4: Team Name | N4: Overall | O4: Non-Negotiable | P4: Achieved
A5: 3 | B5: Amrit Raj Verma | C5: SKS Enterprises | D5: 45985 | E5: c-amrit.verma@bennett.edu.in | F5: Engineering | G5: 50 | H5: 40 | J5: =I5-G5 -> -50 | K5: =I5/G5 -> 0 | M5: Engineering | N5: =Engineering!G30 -> 1250 | O5: =Engineering!H30 -> 1000
A6: 4 | B6: Bhumika Kohli | C6: SKS Enterprises | D6: 46147 | E6: c-bhumika.kohli@bennett.edu.in | F6: Engineering | G6: 50 | H6: 40 | J6: =I6-G6 -> -50 | K6: =I6/G6 -> 0 | M6: Management | N6: =Management!G13 -> 450 | O6: =Management!H13 -> 350
A7: 5 | B7: Deepali Yadav | C7: SKS Enterprises | D7: 46125 | E7: c-deepali.yadav@bennett.edu.in | F7: Engineering | G7: 50 | H7: 40 | J7: =I7-G7 -> -50 | K7: =I7/G7 -> 0 | M7: Law | N7: =Law!G5 -> 100 | O7: =Law!H5 -> 80
A8: 6 | B8: Ishika Singh | C8: SKS Enterprises | D8: 46128 | E8: c-ishika.singh@bennett.edu.in | F8: Engineering | G8: 50 | H8: 40 | J8: =I8-G8 -> -50 | K8: =I8/G8 -> 0 | M8: Media & Liberal Arts | N8: ='Liberal Arts'!G7 -> 175 | O8: ='Liberal Arts'!H7 -> 140
A9: 7 | B9: Md.Arshad Hussain | C9: SKS Enterprises | D9: 45352 | E9: c-arshad.hussain@bennett.edu.in | F9: Engineering | G9: 50 | H9: 40 | J9: =I9-G9 -> -50 | K9: =I9/G9 -> 0 | M9: Design | N9: =Design!G6 -> 100 | O9: =Design!H6 -> 75
A10: 8 | B10: Mishika Jindal | C10: SKS Enterprises | D10: 46034 | E10: c-mishika.jinddal@bennett.edu.in | F10: Engineering | G10: 50 | H10: 40 | J10: =I10-G10 -> -50 | K10: =I10/G10 -> 0 | M10: Inbound | N10: =Inbound!G20 -> 510 | O10: =Inbound!H20 -> 340
A11: 9 | B11: Palki Mittal | C11: AM2PM | D11: 46129 | E11: c-palki.mittal@bennett.edu.in | F11: Engineering | G11: 50 | H11: 40 | J11: =I11-G11 -> -50 | K11: =I11/G11 -> 0 | M11: Grand Total | N11: =SUM(N5:N10) -> 2585 | O11: =SUM(O5:O10) -> 1985
A12: 10 | B12: Pallavi Singh | C12: AM2PM | D12: 46125 | E12: c-pallavi.singh@bennett.edu.in | F12: Engineering | G12: 50 | H12: 40 | J12: =I12-G12 -> -50 | K12: =I12/G12 -> 0
A13: 11 | B13: Ritika Dakolia | C13: SKS Enterprises | D13: 45985 | E13: c-ritika.dakolia@bennett.edu.in | F13: Engineering | G13: 50 | H13: 40 | J13: =I13-G13 -> -50 | K13: =I13/G13 -> 0
A14: 12 | B14: Ritu Raj | C14: SKS Enterprises | D14: 46121 | E14: c-ritu.raj@bennett.edu.in | F14: Engineering | G14: 50 | H14: 40 | J14: =I14-G14 -> -50 | K14: =I14/G14 -> 0
A15: 13 | B15: Roshan Kumar Singh | C15: AM2PM | D15: 46125 | E15: c-roshan.singh@bennett.edu.in | F15: Engineering | G15: 50 | H15: 40 | J15: =I15-G15 -> -50 | K15: =I15/G15 -> 0
A16: 14 | B16: Sakshi Singh | C16: AM2PM | D16: 46128 | E16: c-sakshi.singh@bennett.edu.in | F16: Engineering | G16: 50 | H16: 40 | J16: =I16-G16 -> -50 | K16: =I16/G16 -> 0
A17: 15 | B17: Sanjana Pal | C17: AM2PM | D17: 46132 | E17: c-sanjana.pal@bennett.edu.in | F17: Engineering | G17: 50 | H17: 40 | J17: =I17-G17 -> -50 | K17: =I17/G17 -> 0
A18: 16 | B18: Sanjay Rawat | C18: AM2PM | D18: 46121 | E18: c-sanjay.rawat@bennett.edu.in | F18: Engineering | G18: 50 | H18: 40 | J18: =I18-G18 -> -50 | K18: =I18/G18 -> 0
A19: 17 | B19: Shweta Gupta | C19: SKS Enterprises | D19: 46034 | E19: c-shweta.gupta@bennett.edu.in | F19: Engineering | G19: 50 | H19: 40 | J19: =I19-G19 -> -50 | K19: =I19/G19 -> 0
A20: 18 | B20: Sneha Kumari | C20: SKS Enterprises | D20: 46126 | E20: c-sneha.kumarri@bennett.edu.in | F20: Engineering | G20: 50 | H20: 40 | J20: =I20-G20 -> -50 | K20: =I20/G20 -> 0
A21: 19 | B21: Supriya Singh | C21: SKS Enterprises | D21: 46125 | E21: c-supriya.singh@bennett.edu.in | F21: Engineering | G21: 50 | H21: 40 | J21: =I21-G21 -> -50 | K21: =I21/G21 -> 0
A22: 20 | B22: Surbhi Yadav | C22: AM2PM | D22: 46132 | E22: c-surbhi.yadav@bennett.edu.in | F22: Engineering | G22: 50 | H22: 40 | J22: =I22-G22 -> -50 | K22: =I22/G22 -> 0
A23: 21 | B23: Swati Shandaliya | C23: SKS Enterprises | D23: 46006 | E23: c-swati.shandaliya@bennett.edu.in | F23: Engineering | G23: 50 | H23: 40 | J23: =I23-G23 -> -50 | K23: =I23/G23 -> 0
... A41: 39 | B41: Mihir Kumar | C41: SKS Enterprises | D41: 45962 | E41: c-mihir.kumar@bennett.edu.in | F41: Law | G41: 50 | H41: 40 | J41: =I41-G41 -> -50 | K41: =I41/G41 -> 0
A42: 40 | B42: Prajukta Kashyap | C42: =VLOOKUP(B42,'[1]Media & Liberal Arts'!$A:$J,2,0) -> AM2PM | D42: =VLOOKUP(B42,'[1]Media & Liberal Arts'!$A:$J,3,0) -> 46121 | E42: c-prajukta.kashyap@bennett.edu.in | F42: Media/Liberal Arts | G42: 50 | H42: 40 | J42: =I42-G42 -> -50 | K42: =I42/G42 -> 0
A43: 41 | B43: Shraddha Sharma | C43: =VLOOKUP(B43,'[1]Media & Liberal Arts'!$A:$J,2,0) -> SKS Enterprises | D43: =VLOOKUP(B43,'[1]Media & Liberal Arts'!$A:$J,3,0) -> 46065 | E43: c-shraddha.sharma@bennett.edu.in | F43: Media/Liberal Arts | G43: 50 | H43: 40 | J43: =I43-G43 -> -50 | K43: =I43/G43 -> 0
A44: 42 | B44: Taniya Adhikari | C44: =VLOOKUP(B44,'[1]Media & Liberal Arts'!$A:$J,2,0) -> SKS Enterprises | D44: =VLOOKUP(B44,'[1]Media & Liberal Arts'!$A:$J,3,0) -> 46020 | E44: c-tanya.adhikari@bennett.edu.in | F44: Media/Liberal Arts | G44: 50 | H44: 40 | J44: =I44-G44 -> -50 | K44: =I44/G44 -> 0
A45: 43 | B45: Abquari Akhtar | C45: SKS Enterprises | D45: 46118 | E45: c-abquar.akhtar@bennett.edu.in | F45: Media/Liberal Arts | G45: 25 | H45: 20 | J45: =I45-G45 -> -25 | K45: =I45/G45 -> 0
A46: 44 | B46: Deepanshi Sharma | C46: SKS Enterprises | D46: 46013 | E46: c-deepanshi.sharma@bennett.edu.in | F46: Design | G46: 40 | H46: 30 | J46: =I46-G46 -> -40 | K46: =I46/G46 -> 0
A47: 45 | B47: Nidhi Khandelwal | C47: SKS Enterprises | D47: 46097 | E47: c-nidhi.khandelwal@bennett.edu.in | F47: Design | G47: 40 | H47: 30 | J47: =I47-G47 -> -40 | K47: =I47/G47 -> 0
A48: 46 | B48: Ankita Singh | C48: SKS Enterprises | D48: 46118 | E48: c-ankita.singh1@bennett.edu.in | F48: Design | G48: 20 | H48: 15 | J48: =I48-G48 -> -20 | K48: =I48/G48 -> 0
A49: 47 | B49: Adiba Farid | C49: SKS Enterprises | D49: 46090 | E49: c-abida.farid@bennett.edu.in | F49: Inbound | G49: 30 | H49: 20 | J49: =I49-G49 -> -30 | K49: =I49/G49 -> 0
A50: 48 | B50: Agrim Chaudhary | C50: SKS Enterprises | D50: 46013 | E50: c-agrim.chaudhary@bennett.edu.in | F50: Inbound | G50: 30 | H50: 20 | J50: =I50-G50 -> -30 | K50: =I50/G50 -> 0
A51: 49 | B51: Akanksha Sengar | C51: SKS Enterprises | D51: 46147 | E51: c-akanksha.sengar@bennett.edu.in | F51: Inbound | G51: 30 | H51: 20 | J51: =I51-G51 -> -30 | K51: =I51/G51 -> 0
A52: 50 | B52: Ankita Yadav | C52: AM2PM | D52: 46111 | E52: c-ankita.yadav@bennett.edu.in | F52: Inbound | G52: 30 | H52: 20 | J52: =I52-G52 -> -30 | K52: =I52/G52 -> 0
A53: 51 | B53: Anshika Garg | C53: AM2PM | D53: 46112 | E53: c-anshika.garg@bennett.edu.in | F53: Inbound | G53: 30 | H53: 20 | J53: =I53-G53 -> -30 | K53: =I53/G53 -> 0
A54: 52 | B54: Bhoomi Kanujiya | C54: SKS Enterprises | D54: 46099 | E54: c-bhoomi.kanujiya@bennett.edu.in | F54: Inbound | G54: 30 | H54: 20 | J54: =I54-G54 -> -30 | K54: =I54/G54 -> 0
A55: 53 | B55: Harsh Vardhan | C55: SKS Enterprises | D55: 46162 | E55: c-harsh.vardhan@bennett.edu.in | F55: Inbound | G55: 30 | H55: 20 | J55: =I55-G55 -> -30 | K55: =I55/G55 -> 0
A56: 54 | B56: Safiya Farheen | C56: SKS Enterprises | D56: 46090 | E56: c-safiya.farheen@bennett.edu.in | F56: Inbound | G56: 20 | H56: 10 | J56: =I56-G56 -> -20 | K56: =I56/G56 -> 0
... A65: 63 | B65: Alok Raj | C65: SKS Enterprises | D65: 46054 | E65: c-alok.raj@bennett.edu.in | F65: Inbound | G65: 40 | H65: 20 | J65: =I65-G65 -> -40 | K65: =I65/G65 -> 0
...

Sheet Engineering
A1: August Month Engineering Team Performance Report
A2: S.No | B2: Counsellor Name | C2: Agency Name | D2: DOJ | E2: Email ID | F2: Team Name | G2: Overall | H2: Non-Negotiable | I2: Achieved | J2: Pending | K2: % Achieved
A3: 1 | B3: Abhishek Kumar Singh | C3: SKS Enterprises | D3: 46106 | E3: c-abhishek.singh@bennett.edu.in | F3: Engineering | G3: 50 | H3: 40 | J3: =I3-G3 -> -50 | K3: =I3/G3 -> 0
A4: 2 | B4: Akshat Sharma | C4: SKS Enterprises | D4: 46020 | E4: c-akshat.sharma@bennett.edu.in | F4: Engineering | G4: 50 | H4: 40 | J4: =I4-G4 -> -50 | K4: =I4/G4 -> 0
A5: 3 | B5: Amrit Raj Verma | C5: SKS Enterprises | D5: 45985 | E5: c-amrit.verma@bennett.edu.in | F5: Engineering | G5: 50 | H5: 40 | J5: =I5-G5 -> -50 | K5: =I5/G5 -> 0
A6: 4 | B6: Bhumika Kohli | C6: SKS Enterprises | D6: 46147 | E6: c-bhumika.kohli@bennett.edu.in | F6: Engineering | G6: 50 | H6: 40 | J6: =I6-G6 -> -50 | K6: =I6/G6 -> 0
A7: 5 | B7: Deepali Yadav | C7: SKS Enterprises | D7: 46125 | E7: c-deepali.yadav@bennett.edu.in | F7: Engineering | G7: 50 | H7: 40 | J7: =I7-G7 -> -50 | K7: =I7/G7 -> 0
A8: 6 | B8: Ishika Singh | C8: SKS Enterprises | D8: 46128 | E8: c-ishika.singh@bennett.edu.in | F8: Engineering | G8: 50 | H8: 40 | J8: =I8-G8 -> -50 | K8: =I8/G8 -> 0
A9: 7 | B9: Md.Arshad Hussain | C9: SKS Enterprises | D9: 45352 | E9: c-arshad.hussain@bennett.edu.in | F9: Engineering | G9: 50 | H9: 40 | J9: =I9-G9 -> -50 | K9: =I9/G9 -> 0
A10: 8 | B10: Mishika Jindal | C10: SKS Enterprises | D10: 46034 | E10: c-mishika.jinddal@bennett.edu.in | F10: Engineering | G10: 50 | H10: 40 | J10: =I10-G10 -> -50 | K10: =I10/G10 -> 0
A11: 9 | B11: Palki Mittal | C11: AM2PM | D11: 46129 | E11: c-palki.mittal@bennett.edu.in | F11: Engineering | G11: 50 | H11: 40 | J11: =I11-G11 -> -50 | K11: =I11/G11 -> 0
A12: 10 | B12: Pallavi Singh | C12: AM2PM | D12: 46125 | E12: c-pallavi.singh@bennett.edu.in | F12: Engineering | G12: 50 | H12: 40 | J12: =I12-G12 -> -50 | K12: =I12/G12 -> 0
A13: 10 | B13: Ritika Dakolia | C13: SKS Enterprises | D13: 45985 | E13: c-ritika.dakolia@bennett.edu.in | F13: Engineering | G13: 50 | H13: 40 | J13: =I13-G13 -> -50 | K13: =I13/G13 -> 0
A14: 11 | B14: Ritu Raj | C14: SKS Enterprises | D14: 46121 | E14: c-ritu.raj@bennett.edu.in | F14: Engineering | G14: 50 | H14: 40 | J14: =I14-G14 -> -50 | K14: =I14/G14 -> 0
... A29: 26 | B29: Yogita Singh | C29: AM2PM | D29: 46126 | E29: c-yogita.singh@bennett.edu.in | F29: Engineering | G29: 25 | H29: 20 | J29: =I29-G29 -> -25 | K29: =I29/G29 -> 0
A30: Grand Total | G30: =SUM(G3:G29) -> 1250 | H30: =SUM(H3:H29) -> 1000 | I30: =SUM(I3:I25) -> 0 | J30: =SUM(J3:J29) -> -1250 | K30: =I30/G30 -> 0

Sheet Management
A1: August Month Management Team_Performance Report
A2: S.No | B2: Counsellor Name | C2: Agency Name | D2: DOJ | E2: Email ID | F2: Team Name | G2: Overall | H2: Non-Negotiable | I2: Achieved | J2: Pending | K2: % Achieved
A3: 1 | B3: Abhinav Kumar | C3: SKS Enterprises | D3: 46104 | E3: c-abhinav.kumar@bennett.edu.in | F3: Management | G3: 50 | H3: 40 | J3: =I3-G3 -> -50 | K3: =I3/G3 -> 0
A4: 2 | B4: Arvind Kumar | C4: SKS Enterprises | D4: 46125 | E4: c-arvind.kumar@bennett.edu.in | F4: Management | G4: 50 | H4: 40 | J4: =I4-G4 -> -50 | K4: =I4/G4 -> 0
A5: 3 | B5: Ashna Sidiqqui | C5: AM2PM | D5: 46128 | E5: c-ashna.sidiqqui@bennett.edu.in | F5: Management | G5: 50 | H5: 40 | J5: =I5-G5 -> -50 | K5: =I5/G5 -> 0
A6: 4 | B6: Bashar Nasir | C6: SKS Enterprises | D6: 46218 | E6: c-bashar.nasir@bennett.edu.in | F6: Management | G6: 20 | H6: 10 | J6: =I6-G6 -> -20 | K6: =I6/G6 -> 0
A7: 5 | B7: Hemant Singh | C7: AM2PM | D7: 46181 | E7: c-hemant.singh@bennett.edu.in | F7: Management | G7: 40 | H7: 30 | J7: =I7-G7 -> -40 | K7: =I7/G7 -> 0
A8: 6 | B8: Nikhil Pal | C8: AM2PM | D8: 46153 | E8: c-nikhil.pal@bennett.edu.in | F8: Management | G8: 40 | H8: 30 | J8: =I8-G8 -> -40 | K8: =I8/G8 -> 0
A9: 7 | B9: Shalini Panjiyar | C9: SKS Enterprises | D9: 46006 | E9: c-shalini.paniyar@bennett.edu.in | F9: Management | G9: 50 | H9: 40 | J9: =I9-G9 -> -50 | K9: =I9/G9 -> 0
A10: 8 | B10: Shivansh Tyagi | C10: SKS Enterprises | D10: 46125 | E10: c-shivansh.tyagi@bennett.edu.in | F10: Management | G10: 50 | H10: 40 | J10: =I10-G10 -> -50 | K10: =I10/G10 -> 0
A11: 9 | B11: Tanushree Baisala | C11: SKS Enterprises | D11: 46006 | E11: c-tanushree.bansal@bennett.edu.in | F11: Management | G11: 50 | H11: 40 | J11: =I11-G11 -> -50 | K11: =I11/G11 -> 0
A12: 10 | B12: Tanya Yadav | C12: SKS Enterprises | D12: 46128 | E12: c-tanya.yadav@bennett.edu.in | F12: Management | G12: 50 | H12: 40 | J12: =I12-G12 -> -50 | K12: =I12/G12 -> 0
A13: Grand Total | G13: =SUM(G3:G12) -> 450 | H13: =SUM(H3:H12) -> 350 | I13: =SUM(I3:I12) -> 0 | J13: =SUM(J3:J12) -> -450 | K13: =I13/G13 -> 0

Sheet Law
A1: August Month Law Team Performance Report
A2: S.No | B2: Counsellor Name | C2: Agency Name | D2: DOJ | E2: Email ID | F2: Team Name | G2: Overall | H2: Non-Negotiable | I2: Achieved | J2: Pending | K2: % Achieved
A3: 1 | B3: Debjani Saha | C3: SKS Enterprises | D3: 46090 | E3: c-debanjani.saha@bennett.edu.in | F3: Law | G3: 50 | H3: 40 | J3: =I3-G3 -> -50 | K3: =I3/G3 -> 0
A4: 2 | B4: Mihir Kumar | C4: SKS Enterprises | D4: 45962 | E4: c-mihir.kumar@bennett.edu.in | F4: Law | G4: 50 | H4: 40 | J4: =I4-G4 -> -50 | K4: =I4/G4 -> 0
A5: Grand Total | G5: =SUM(G3:G4) -> 100 | H5: =SUM(H3:H4) -> 80 | I5: =SUM(I3:I4) -> 0 | J5: =SUM(J3:J4) -> -100 | K5: =I5/G5 -> 0

Sheet Liberal Arts
A1: August Month Media/Liberal Arts Team_Performance Report
A2: S.No | B2: Counsellor Name | C2: Agency Name | D2: DOJ | E2: Email ID | F2: Team Name | G2: Overall | H2: Non-Negotiable | I2: Achieved | J2: Pending | K2: % Achieved
A3: 1 | B3: Prajukta Kashyap | C3: =VLOOKUP(B3,'[1]Media & Liberal Arts'!$A:$J,2,0) -> AM2PM | D3: =VLOOKUP(B3,'[1]Media & Liberal Arts'!$A:$J,3,0) -> 46121 | E3: c-prajukta.kashyap@bennett.edu.in | F3: Media/Liberal Arts | G3: 50 | H3: 40 | J3: =I3-G3 -> -50 | K3: =I3/G3 -> 0
A4: 2 | B4: Shraddha Sharma | C4: =VLOOKUP(B4,'[1]Media & Liberal Arts'!$A:$J,2,0) -> SKS Enterprises | D4: =VLOOKUP(B4,'[1]Media & Liberal Arts'!$A:$J,3,0) -> 46065 | E4: c-shraddha.sharma@bennett.edu.in | F4: Media/Liberal Arts | G4: 50 | H4: 40 | J4: =I4-G4 -> -50 | K4: =I4/G4 -> 0
A5: 3 | B5: Taniya Adhikari | C5: =VLOOKUP(B5,'[1]Media & Liberal Arts'!$A:$J,2,0) -> SKS Enterprises | D5: =VLOOKUP(B5,'[1]Media & Liberal Arts'!$A:$J,3,0) -> 46020 | E5: c-tanya.adhikari@bennett.edu.in | F5: Media/Liberal Arts | G5: 50 | H5: 40 | J5: =I5-G5 -> -50 | K5: =I5/G5 -> 0
A6: 4 | B6: Abquari Akhtar | C6: SKS Enterprises | D6: 46118 | E6: c-abquar.akhtar@bennett.edu.in | F6: Media/Liberal Arts | G6: 25 | H6: 20 | J6: =I6-G6 -> -25 | K6: =I6/G6 -> 0
A7: Grand Total | G7: =SUM(G3:G6) -> 175 | H7: =SUM(H3:H6) -> 140 | I7: =SUM(I3:I5) -> 0 | J7: =SUM(J3:J6) -> -175 | K7: =I7/G7 -> 0

Sheet Design
A1: Design Month Design Team_Performance Report
A2: S.No | B2: Counsellor Name | C2: Agency Name | D2: DOJ | E2: Email ID | F2: Team Name | G2: Overall | H2: Non-Negotiable | I2: Achieved | J2: Pending | K2: % Achieved
A3: 1 | B3: Deepanshi Sharma | C3: SKS Enterprises | D3: 46013 | E3: c-deepanshi.sharma@bennett.edu.in | F3: Design | G3: 40 | H3: 30 | J3: =I3-G3 -> -40 | K3: =I3/G3 -> 0
A4: 2 | B4: Nidhi Khandelwal | C4: SKS Enterprises | D4: 46097 | E4: c-nidhi.khandelwal@bennett.edu.in | F4: Design | G4: 40 | H4: 30 | J4: =I4-G4 -> -40 | K4: =I4/G4 -> 0
A5: 3 | B5: Ankita Singh | C5: SKS Enterprises | D5: 46118 | E5: c-ankita.singh1@bennett.edu.in | F5: Design | G5: 20 | H5: 15 | J5: =I5-G5 -> -20 | K5: =I5/G5 -> 0
A6: Grand Total | G6: =SUM(G3:G5) -> 100 | H6: =SUM(H3:H5) -> 75 | I6: =SUM(I3:I4) -> 0 | J6: =SUM(J3:J5) -> -100 | K6: =I6/G6 -> 0

Sheet Inbound
A1: August Month Inbound Team Performance Report
A2: S.No | B2: Counsellor Name | C2: Agency Name | D2: DOJ | E2: Email ID | F2: Team Name | G2: Overall | H2: Non-Negotiable | I2: Achieved | J2: Pending | K2: % Achieved
A3: 1 | B3: Adiba Farid | C3: SKS Enterprises | D3: 46090 | E3: c-abida.farid@bennett.edu.in | F3: Inbound | G3: 30 | H3: 20 | J3: =I3-G3 -> -30 | K3: =I3/G3 -> 0
A4: 2 | B4: Agrim Chaudhary | C4: SKS Enterprises | D4: 46013 | E4: c-agrim.chaudhary@bennett.edu.in | F4: Inbound | G4: 30 | H4: 20 | J4: =I4-G4 -> -30 | K4: =I4/G4 -> 0
A5: 3 | B5: Akanksha Sengar | C5: SKS Enterprises | D5: 46147 | E5: c-akanksha.sengar@bennett.edu.in | F5: Inbound | G5: 30 | H5: 20 | J5: =I5-G5 -> -30 | K5: =I5/G5 -> 0
A6: 4 | B6: Ankita Yadav | C6: AM2PM | D6: 46111 | E6: c-ankita.yadav@bennett.edu.in | F6: Inbound | G6: 30 | H6: 20 | J6: =I6-G6 -> -30 | K6: =I6/G6 -> 0
A7: 5 | B7: Anshika Garg | C7: AM2PM | D7: 46112 | E7: c-anshika.garg@bennett.edu.in | F7: Inbound | G7: 30 | H7: 20 | J7: =I7-G7 -> -30 | K7: =I7/G7 -> 0
A8: 6 | B8: Bhoomi Kanujiya | C8: SKS Enterprises | D8: 46099 | E8: c-bhoomi.kanujiya@bennett.edu.in | F8: Inbound | G8: 30 | H8: 20 | J8: =I8-G8 -> -30 | K8: =I8/G8 -> 0
A9: 7 | B9: Harsh Vardhan | C9: SKS Enterprises | D9: 46162 | E9: c-harsh.vardhan@bennett.edu.in | F9: Inbound | G9: 30 | H9: 20 | J9: =I9-G9 -> -30 | K9: =I9/G9 -> 0
A10: 8 | B10: Safiya Farheen | C10: SKS Enterprises | D10: 46090 | E10: c-safiya.farheen@bennett.edu.in | F10: Inbound | G10: 20 | H10: 10 | J10: =I10-G10 -> -20 | K10: =I10/G10 -> 0
A11: 9 | B11: Sakaar Srivastava | C11: SKS Enterprises | D11: 46147 | E11: c-sakaar.srivastava@bennett.edu.in | F11: Inbound | G11: 30 | H11: 20 | J11: =I11-G11 -> -30 | K11: =I11/G11 -> 0
A12: 10 | B12: Shalini Kumari | C12: SKS Enterprises | D12: 46020 | E12: c-shalini.kumari@bennett.edu.in | F12: Inbound | G12: 30 | H12: 20 | J12: =I12-G12 -> -30 | K12: =I12/G12 -> 0
A13: 11 | B13: Sneha Gupta | C13: SKS Enterprises | D13: 46167 | E13: c-sneha.gupta@bennett.edu.in | F13: Inbound | G13: 30 | H13: 20 | J13: =I13-G13 -> -30 | K13: =I13/G13 -> 0
A14: 12 | B14: Sukriti Shukla | C14: SKS Enterprises | D14: 46125 | E14: c-sukriti.shukla@bennett.edu.in | F14: Inbound | G14: 30 | H14: 20 | J14: =I14-G14 -> -30 | K14: =I14/G14 -> 0
... A18: 16 | B18: Deepali Gupta | C18: SKS Enterprises | D18: 45705 | E18: c-deepali.gupta@bennett.edu.in | F18: Inbound | G18: 30 | H18: 20 | J18: =I18-G18 -> -30 | K18: =I18/G18 -> 0
A19: 16 | B19: Alok Raj | F19: Inbound | G19: 40 | H19: 30 | J19: =I19-G19 -> -40 | K19: =I19/G19 -> 0
A20: Grand Total | G20: =SUM(G3:G19) -> 510 | H20: =SUM(H3:H19) -> 340 | I20: =SUM(I3:I18) -> 0 | J20: =SUM(J3:J19) -> -510 | K20: =I20/G20 -> 0
